Workbook

Sheet Pipeline Flow (Simple KPI)
B1: PROPKART CRM — LEAD PIPELINE FLOW & KPI COUNTER
B2: Simplified Funnel: Leads In -> Telecaller Allocation -> Status -> Sales Handoff -> Closure • Real-Time Dynamic Date Filtering
B3: Select Timeframe Filter: | C3: This Week | D3: Active Filter Window: | E3: =TEXT(F4, "YYYY-MM-DD") & " to " & TEXT(G4, "YYYY-MM-DD") -> 2026-09-22 to 2026-09-28
B4: Available Filter Options: | C4: Dropdown choices in C3: [ All Time ] • [ Today ] • [ This Week ] • [ This Month ] • [ Custom Range ] | F4: =IF(C3="Today", DATE(2026,9,28), IF(C3="This Week", DATE(2026,9,22), IF(C3="This Month", DATE(2026,9,1), IF(C3="All Time", DATE(2020,1,1), C5)))) -> 46287 | G4: =IF(C3="Today", DATE(2026,9,28), IF(C3="This Week", DATE(2026,9,28), IF(C3="This Month", DATE(2026,9,28), IF(C3="All Time", DATE(2030,12,31), E5)))) -> 46293
B5: If 'Custom Range' selected: | C5: 46220 | D5: to | E5: 46293
B7: PIPELINE FLOW STAGE | C7: CURRENT KPI COUNT | D7: % SHARE / CONVERSION | E7: STAGE DESCRIPTION
B8: STAGE 1:HOW MANY LEADS GET IN
B9: Total leads we got | C9: =COUNTIFS(Requirement!$A:$A, ">="&$F$4, Requirement!$A:$A, "<="&$G$4+1) + COUNTIFS(Listing!$A:$A, ">="&$F$4, Listing!$A:$A, "<="&$G$4+1) -> 211 | D9: 100.0% | E9: Combined intake across all channels (Meta, Housing, Webhook, Direct)
B10: Requirement leads | C10: =COUNTIFS(Requirement!$A:$A, ">="&$F$4, Requirement!$A:$A, "<="&$G$4+1) -> 120 | D10: =IF($C$9>0, C10/$C$9, 0) -> 0.56872038 | E10: Clients looking to rent or buy property
B11: Listing leads | C11: =COUNTIFS(Listing!$A:$A, ">="&$F$4, Listing!$A:$A, "<="&$G$4+1) -> 91 | D11: =IF($C$9>0, C11/$C$9, 0) -> 0.43127962 | E11: Owners submitting property listings
B12: STAGE 2: TELECALLER ALLOCATION & QUEUE
B13: From total leads the allocation engine allocated leads | C13: =C9 - C14 -> 197 | D13: =IF($C$9>0, C13/$C$9, 0) -> 0.93364929 | E13: Inquiries assigned to active telecallers for calling
B14: Allocated but waiting in queue | C14: =COUNTIFS(Requirement!$A:$A, ">="&$F$4, Requirement!$A:$A, "<="&$G$4+1, Requirement!$E:$E, "Unassigned") + COUNTIFS(Listing!$A:$A, ">="&$F$4, Listing!$A:$A, "<="&$G$4+1, Listing!$E:$E, "Unassigned") -> 14 | D14: =IF($C$9>0, C14/$C$9, 0) -> 0.066350711 | E14: Awaiting telecaller assignment or direct intake
B15: STAGE 3: TELECALLER CALL OUTCOMES (WHAT IS ITS STATUS)
B16: • New / In Telecaller Calling Queue | C16: =COUNTIFS(Requirement!$A:$A, ">="&$F$4, Requirement!$A:$A, "<="&$G$4+1, Requirement!$F:$F, "New") + COUNTIFS(Listing!$A:$A, ">="&$F$4, Listing!$A:$A, "<="&$G$4+1, Listing!$F:$F, "New") -> 131 | D16: =IF($C$9>0, C16/$C$9, 0) -> 0.62085308 | E16: Assigned to telecaller, awaiting first call connect
B17: • Combined number of leads telecaller marked CNR | C17: =COUNTIFS(Requirement!$A:$A, ">="&$F$4, Requirement!$A:$A, "<="&$G$4+1, Requirement!$F:$F, "*CNR*") + COUNTIFS(Listing!$A:$A, ">="&$F$4, Listing!$A:$A, "<="&$G$4+1, Listing!$F:$F, "*CNR*") -> 10 | D17: =IF($C$9>0, C17/$C$9, 0) -> 0.047393365 | E17: Call placed; client phone rang or unanswered
B18: • Callback Scheduled | C18: =COUNTIFS(Requirement!$A:$A, ">="&$F$4, Requirement!$A:$A, "<="&$G$4+1, Requirement!$F:$F, "*Callback*") + COUNTIFS(Listing!$A:$A, ">="&$F$4, Listing!$A:$A, "<="&$G$4+1, Listing!$F:$F, "*Callback*") -> 3 | D18: =IF($C$9>0, C18/$C$9, 0) -> 0.014218009 | E18: Client requested follow-up at specific time
B19: • Interested | C19: =COUNTIFS(Requirement!$A:$A, ">="&$F$4, Requirement!$A:$A, "<="&$G$4+1, Requirement!$F:$F, "Interested") + COUNTIFS(Listing!$A:$A, ">="&$F$4, Listing!$A:$A, "<="&$G$4+1, Listing!$F:$F, "Interested") -> 1 | D19: =IF($C$9>0, C19/$C$9, 0) -> 0.0047393365 | E19: Client confirmed criteria; collecting preferences
B20: • Not interested | C20: =COUNTIFS(Requirement!$A:$A, ">="&$F$4, Requirement!$A:$A, "<="&$G$4+1, Requirement!$F:$F, "Rejected*") + COUNTIFS(Requirement!$A:$A, ">="&$F$4, Requirement!$A:$A, "<="&$G$4+1, Requirement!$F:$F, "Archived") + COUNTIFS(Listing!$A:$A, ">="&$F$4, Listing!$A:$A, "<="&$G$4+1, Listing!$F:$F, "Rejected*") -> 18 | D20: =IF($C$9>0, C20/$C$9, 0) -> 0.085308057 | E20: No requirement, budget/location mismatch, or wrong number
B21: • Verified & Listed on PropKart | C21: =COUNTIFS(Listing!$A:$A, ">="&$F$4, Listing!$A:$A, "<="&$G$4+1, Listing!$F:$F, "Listed*") -> 17 | D21: =IF($C$9>0, C21/$C$9, 0) -> 0.08056872 | E21: Owner inquiry verified and published live on portal
B22: STAGE 4: SALES TEAM ALLOCATION (THE 6 PEOPLE & PROPKART ADMIN)
B23: Total Qualified Leads Handed to Sales | C23: =COUNTIFS(Requirement!$A:$A, ">="&$F$4, Requirement!$A:$A, "<="&$G$4+1, Requirement!$G:$G, "<>Not Assigned") + COUNTIFS(Listing!$A:$A, ">="&$F$4, Listing!$A:$A, "<="&$G$4+1, Listing!$G:$G, "<>Not Assigned", Listing!$G:$G, "<>PropKart Direct") -> 50 | D23: =IF($C$9>0, C23/$C$9, 0) -> 0.23696682 | E23: Qualified leads assigned to Sales Executives
B24: • Rajan Purani | C24: =COUNTIFS(Requirement!$A:$A, ">="&$F$4, Requirement!$A:$A, "<="&$G$4+1, Requirement!$G:$G, "Rajan Purani") + COUNTIFS(Listing!$A:$A, ">="&$F$4, Listing!$A:$A, "<="&$G$4+1, Listing!$G:$G, "Rajan Purani") -> 8 | D24: =IF($C$23>0, C24/$C$23, 0) -> 0.16 | E24: Sales Team Lead • High-value requirement allocation
B25: • Rakesh Jadav | C25: =COUNTIFS(Requirement!$A:$A, ">="&$F$4, Requirement!$A:$A, "<="&$G$4+1, Requirement!$G:$G, "Rakesh Jadav") + COUNTIFS(Listing!$A:$A, ">="&$F$4, Listing!$A:$A, "<="&$G$4+1, Listing!$G:$G, "Rakesh Jadav") -> 15 | D25: =IF($C$23>0, C25/$C$23, 0) -> 0.3 | E25: Senior Sales • Key client portfolio management
B26: • Somel Rathod | C26: =COUNTIFS(Requirement!$A:$A, ">="&$F$4, Requirement!$A:$A, "<="&$G$4+1, Requirement!$G:$G, "Somel Rathod") + COUNTIFS(Listing!$A:$A, ">="&$F$4, Listing!$A:$A, "<="&$G$4+1, Listing!$G:$G, "Somel Rathod") -> 12 | D26: =IF($C$23>0, C26/$C$23, 0) -> 0.24 | E26: Senior Sales • Active client matching & property visits
B27: • Viral Jadeja | C27: =COUNTIFS(Requirement!$A:$A, ">="&$F$4, Requirement!$A:$A, "<="&$G$4+1, Requirement!$G:$G, "Viral Jadeja") + COUNTIFS(Listing!$A:$A, ">="&$F$4, Listing!$A:$A, "<="&$G$4+1, Listing!$G:$G, "Viral Jadeja") -> 9 | D27: =IF($C$23>0, C27/$C$23, 0) -> 0.18 | E27: Sales Executive • Client outreach & site visits
B28: • Prexa Vithalapara | C28: =COUNTIFS(Requirement!$A:$A, ">="&$F$4, Requirement!$A:$A, "<="&$G$4+1, Requirement!$E:$E, "Prexa Vithalapara") + COUNTIFS(Listing!$A:$A, ">="&$F$4, Listing!$A:$A, "<="&$G$4+1, Listing!$E:$E, "Prexa Vithalapara") -> 38 | D28: =IF($C$9>0, C28/$C$9, 0) -> 0.18009479 | E28: Core Telecaller • Inquiries processed
B29: • Zeel Mudaliyar | C29: =COUNTIFS(Requirement!$A:$A, ">="&$F$4, Requirement!$A:$A, "<="&$G$4+1, Requirement!$E:$E, "Zeel Mudaliyar") + COUNTIFS(Listing!$A:$A, ">="&$F$4, Listing!$A:$A, "<="&$G$4+1, Listing!$E:$E, "Zeel Mudaliyar") -> 150 | D29: =IF($C$9>0, C29/$C$9, 0) -> 0.71090047 | E29: Core Telecaller • Inquiries processed
B30: • Propkart Admin (Admin - Operations & Inventory) | C30: =COUNTIFS('Inventory (Total Properties)'!$A:$A, ">="&$F$4, 'Inventory (Total Properties)'!$A:$A, "<="&$G$4+1, 'Inventory (Total Properties)'!$Q:$Q, "Propkart Admin") -> 16 | D30: - | E30: System Admin • Direct CRM inventory creation & management
B31: STAGE 5: SALES PIPELINE OUTCOMES (CONVERSION & CLOSURE)
B32: • Assigned / In Active Follow-up & Discussion | C32: =COUNTIFS(Requirement!$A:$A, ">="&$F$4, Requirement!$A:$A, "<="&$G$4+1, Requirement!$H:$H, "*Follow*") + COUNTIFS(Requirement!$A:$A, ">="&$F$4, Requirement!$A:$A, "<="&$G$4+1, Requirement!$H:$H, "Interested") + COUNTIFS(Requirement!$A:$A, ">="&$F$4, Requirement!$A:$A, "<="&$G$4+1, Requirement!$H:$H, "Live") + COUNTIFS(Requirement!$A:$A, ">="&$F$4, Requirement!$A:$A, "<="&$G$4+1, Requirement!$H:$H, "Assigned*") -> 24 | D32: =IF($C$23>0, C32/$C$23, 0) -> 0.48 | E32: Clients in active discussions with sales team
B33: • Site Visits Scheduled | C33: =COUNTIFS(Requirement!$A:$A, ">="&$F$4, Requirement!$A:$A, "<="&$G$4+1, Requirement!$H:$H, "*Visit Scheduled*") -> 0 | D33: =IF($C$23>0, C33/$C$23, 0) -> 0 | E33: Physical property visits scheduled with client
B34: • Site Visits Completed / Done | C34: =COUNTIFS(Requirement!$A:$A, ">="&$F$4, Requirement!$A:$A, "<="&$G$4+1, Requirement!$H:$H, "*Visit Done*") -> 1 | D34: =IF($C$23>0, C34/$C$23, 0) -> 0.02 | E34: Physical walkthrough executed with sales executive
B35: Deals Won / Closed (Converted to Revenue) | C35: =COUNTIFS(Requirement!$A:$A, ">="&$F$4, Requirement!$A:$A, "<="&$G$4+1, Requirement!$H:$H, "*Won*") -> 0 | D35: =IF($C$23>0, C35/$C$23, 0) -> 0 | E35: Successfully closed rental / resale commercial deals
B36: • Disqualified / Rejected by Sales | C36: =COUNTIFS(Requirement!$A:$A, ">="&$F$4, Requirement!$A:$A, "<="&$G$4+1, Requirement!$H:$H, "Rejected*") + COUNTIFS(Requirement!$A:$A, ">="&$F$4, Requirement!$A:$A, "<="&$G$4+1, Requirement!$H:$H, "Disqualified*") -> 12 | D36: =IF($C$23>0, C36/$C$23, 0) -> 0.24 | E36: Inquiries closed by sales without deal conversion
B37: STAGE 6: PROPKART INVENTORY PORTFOLIO (TOTAL PROPERTIES)
B38: Total Properties in Inventory | C38: =COUNTIFS('Inventory (Total Properties)'!$A:$A, ">="&$F$4, 'Inventory (Total Properties)'!$A:$A, "<="&$G$4+1) -> 28 | D38: 100.0% | E38: Verified properties in PropKart inventory database
B39: • Available Properties (Ready for Matching) | C39: =COUNTIFS('Inventory (Total Properties)'!$A:$A, ">="&$F$4, 'Inventory (Total Properties)'!$A:$A, "<="&$G$4+1, 'Inventory (Total Properties)'!$G:$G, "Available") -> 24 | D39: =IF($C$38>0, C39/$C$38, 0) -> 0.85714286 | E39: Active properties ready for immediate tenant/buyer walkthrough
B40: • Rented Out Properties (Closed Deals) | C40: =COUNTIFS('Inventory (Total Properties)'!$A:$A, ">="&$F$4, 'Inventory (Total Properties)'!$A:$A, "<="&$G$4+1, 'Inventory (Total Properties)'!$G:$G, "Rented Out") -> 4 | D40: =IF($C$38>0, C40/$C$38, 0) -> 0.14285714 | E40: Leased properties closed on PropKart
B41: • Sold Out / Other Properties | C41: =COUNTIFS('Inventory (Total Properties)'!$A:$A, ">="&$F$4, 'Inventory (Total Properties)'!$A:$A, "<="&$G$4+1, 'Inventory (Total Properties)'!$G:$G, "Sold Out") + COUNTIFS('Inventory (Total Properties)'!$A:$A, ">="&$F$4, 'Inventory (Total Properties)'!$A:$A, "<="&$G$4+1, 'Inventory (Total Properties)'!$G:$G, "To Be Available") -> 0 | D41: =IF($C$38>0, C41/$C$38, 0) -> 0 | E41: Outright sales and properties under upcoming notice

Sheet Executive KPI Dashboard
A1: PROPKART CRM — EXECUTIVE KPI & TIME-SERIES WORKLOAD DASHBOARD
A2: Authoritative Hostinger Database Audit • All-Time: 17-Jul-2026 to 28-Sep-2026 (73 Days Active) • Generated on: 28-Sep-2026 06:13 PM IST
A4: 📅 INTERACTIVE DATE FILTER: | B4: From Date (YYYY-MM-DD): | C4: 46220 | D4: To Date (YYYY-MM-DD): | E4: 46293 | F4: Quick Presets: | G4: Today (28-Sep) | H4: This Week (22 to 28-Sep) | I4: This Month (Sep 2026)
A5: 💡 Operational Usage Guide: | B5: To filter by custom dates, edit cells C4 & E4. In data sheets (Listing, Requirement, Inventory), click Column A 'Date Filters' or Column B 'date filter' dropdown.
A7: =COUNTIFS(Requirement!$A:$A, ">="&$C$4, Requirement!$A:$A, "<="&$E$4+1) + COUNTIFS(Listing!$A:$A, ">="&$C$4, Listing!$A:$A, "<="&$E$4+1) -> 1215 | B7: =COUNTIFS(Requirement!$A:$A, ">="&$C$4, Requirement!$A:$A, "<="&$E$4+1) -> 735 | C7: =COUNTIFS(Listing!$A:$A, ">="&$C$4, Listing!$A:$A, "<="&$E$4+1) -> 480 | D7: =COUNTIFS('Inventory (Total Properties)'!$A:$A, ">="&$C$4, 'Inventory (Total Properties)'!$A:$A, "<="&$E$4+1) -> 144 | E7: 1136 | F7: 144 | G7: 3
A8: DYNAMIC TOTAL LEADS (Filtered Inquiries) | B8: DYNAMIC REQUIREMENTS (Tenant / Buyer Leads) | C8: DYNAMIC LISTINGS (Owner Listing Inquiries) | D8: DYNAMIC INVENTORY ADDED (Properties Added) | E8: TOTAL ALL-TIME LEADS (All Ingested Leads) | F8: ACTIVE LIVE INVENTORY (Total PropKart Portfolio) | G8: TOTAL DEALS WON (Converted to Revenue)
A10: 1. MULTI-TIMEFRAME EXECUTIVE PERFORMANCE SUMMARY (TODAY, WEEKLY, MONTHLY, YEARLY)
A11: Executive CRM Performance Metric | B11: Today (28-Sep) | C11: Weekly (Last 7 Days) | D11: Monthly (Sep 2026) | E11: Yearly / All-Time (2026) | F11: % of All-Time | G11: Operational Flow & Business Impact
A12: Total Leads Ingested | B12: 16 | C12: 252 | D12: 1089 | E12: 1136 | F12: 100.0% | G12: Unified ingestion across Meta, Housing, Webhook & Direct
A13: • Meta Ads (Facebook & Instagram) | B13: 12 | C13: 185 | D13: 798 | E13: 831 | F13: 73.2% | G13: Core paid social campaign performance
A14: • Webhook API (External Feeds) | B14: 2 | C14: 28 | D14: 114 | E14: 120 | F14: 10.6% | G14: Automated inbound campaign feeds
A15: • Housing.com (Pahal API Auto-Sync) | B15: 1 | C15: 23 | D15: 94 | E15: 98 | F15: 8.6% | G15: Automated portal synchronization
A16: • Direct / Manual CRM Entry | B16: 1 | C16: 16 | D16: 83 | E16: 86 | F16: 7.6% | G16: Walk-in inquiries and manual intake
A17: • Organic Social Media | B17: 0 | C17: 0 | D17: 0 | E17: 1 | F17: 0.1% | G17: Brand organic engagement
A18: Property Listing Inquiries | B18: 4 | C18: 94 | D18: 385 | E18: 402 | F18: 35.4% | G18: Landlord / property owner inquiries
A19: Client Requirement Inquiries | B19: 12 | C19: 158 | D19: 704 | E19: 734 | F19: 64.6% | G19: Tenant / commercial buyer inquiries
A20: Leads Allocated to Telecallers | B20: 15 | C20: 238 | D20: 865 | E20: 892 | F20: 78.5% | G20: Actively distributed to telecaller calling queues
A21: Unallocated Leads in Queue | B21: 1 | C21: 14 | D21: 224 | E21: 244 | F21: 21.5% | G21: Awaiting round-robin assignment or direct conversions
A22: Leads Handed Over to Sales Team | B22: 2 | C22: 43 | D22: 225 | E22: 274 | F22: 24.1% | G22: Qualified prospects transferred to Sales Executives
A23: Site Visits Officially Scheduled | B23: 0 | C23: 8 | D23: 31 | E23: 34 | F23: - | G23: Physical client property walkthroughs scheduled
... A27: TOTAL DATABASE INGESTION | B27: 16 | C27: 252 | D27: 1089 | E27: 1136 | F27: 100.0% | G27: Complete authoritative database accounting
A29: 2. KEY PERSONNEL PERFORMANCE MATRIX (THE 6 CORE TEAM MEMBERS & PROPKART ADMIN)
A30: Team Member Name | B30: Designation / CRM Role | C30: Today (28-Sep) | D30: Weekly (7 Days) | E30: Monthly (Sep) | F30: Yearly / Total | G30: Requirements | H30: Listings | I30: Current Pipeline Status & Key Conversion | J30: Properties in Inventory
A31: Viral Jadeja | B31: Sales Executive | C31: 1 | D31: 10 | E31: 21 | F31: 21 | G31: 19 | H31: 2 | I31: Active Sales • 21 Assigned • 1 Inventory Onboarded | J31: 1
A32: Prexa Vithalapara | B32: Telecaller | C32: 2 | D32: 43 | E32: 466 | F32: 466 | G32: 300 | H32: 166 | I32: Active Telecaller • 466 Allocated • High Volume Queue | J32: 2
A33: Zeel Mudaliyar | B33: Telecaller | C33: 13 | D33: 147 | E33: 426 | F33: 426 | G33: 231 | H33: 195 | I33: Active Telecaller • 426 Allocated • Lead Qualification Lead | J33: 6
A34: Somel Rathod | B34: Senior Sales Executive | C34: 0 | D34: 12 | E34: 50 | F34: 59 | G34: 55 | H34: 4 | I34: Active Sales • 59 Assigned • 23 Properties in Inventory | J34: 23
A35: Rakesh Jadav | B35: Senior Sales Executive | C35: 0 | D35: 13 | E35: 68 | F35: 86 | G35: 83 | H35: 3 | I35: Senior Sales • 86 Assigned • 33 Properties in Inventory | J35: 33
A36: Rajan Purani | B36: Sales Team Leader | C36: 1 | D36: 8 | E36: 86 | F36: 100 | G36: 97 | H36: 3 | I36: Sales Team Lead • 100 Assigned • 23 Properties in Inventory | J36: 23
A37: Propkart Admin | B37: Admin & Operations Lead | C37: 0 | D37: 0 | E37: 32 | F37: 64 | G37: 64 | H37: 0 | I37: System Admin • 30 Properties Added • 27 Site Visits Scheduled | J37: 30
A38: Daksh Jasoliya | B38: Telecaller / Field Support | C38: 0 | D38: 0 | E38: 0 | F38: 0 | G38: 0 | H38: 0 | I38: Registered Telecaller • 26 Properties Onboarded | J38: 26
A39: TOTAL KEY PERSONNEL WORKLOAD | B39: Core Team Total | C39: 17 | D39: 233 | E39: 1149 | F39: 1222 | G39: 849 | H39: 373 | I39: Full Core Team Workload Across All Departments | J39: 144
A41: 3. TELECALLER CALL OUTCOMES & DISPOSITIONS (TODAY, WEEKLY, MONTHLY, YEARLY)
A42: Telecaller Pipeline Outcome | B42: Today | C42: Weekly (7 Days) | D42: Monthly (Sep) | E42: Yearly / Total | F42: Listing Leads | G42: Requirement Leads | H42: Share (%) | I42: Next Operational Trigger
A43: New / Open (In Telecaller Queue) | B43: 10 | C43: 122 | D43: 356 | E43: 380 | F43: 204 | G43: 176 | H43: 33.5% | I43: Queued for immediate calling outreach
A44: CNR (Could Not Reach / Unanswered) | B44: 3 | C44: 52 | D44: 154 | E44: 163 | F44: 75 | G44: 88 | H44: 14.3% | I44: Retried across morning/evening calling slots
A45: Callback Scheduled | B45: 1 | C45: 7 | D45: 24 | E45: 26 | F45: 16 | G45: 10 | H45: 2.3% | I45: Calendar follow-up scheduled with client
A46: Interested (In Nurturing / Sourcing) | B46: 1 | C46: 38 | D46: 149 | E46: 158 | F46: 43 | G46: 115 | H46: 13.9% | I46: Collecting exact preferences for handoff
A47: Picked Up & Handed to Sales | B47: 1 | C47: 29 | D47: 144 | E47: 152 | F47: 10 | G47: 142 | H47: 13.4% | I47: Direct handoff to assigned sales executive
A48: Property Listed on PropKart | B48: 0 | C48: 4 | D48: 19 | E48: 21 | F48: 21 | G48: 0 | H48: 1.8% | I48: Verified owner inquiry published to portal
...

Sheet Listing
A1: date | B1: date filter | C1: lead source | D1: lead name | E1: allocated telecaller | F1: current status | G1: if assigned -- sales user name | H1: sales user toggled current status | I1: remarks
A2: 46293.653 | B2: 1. Today (28-Sep) | C2: Meta Ads (NB PropertyTech Rental Ad 0408) | D2: ब्राह्मण (6006452344) | E2: Zeel Mudaliyar | F2: New | G2: Not Assigned | H2: N/A (Not Assigned) | I2: -
A3: 46293.487 | B3: 1. Today (28-Sep) | C3: Meta Ads (NB PropertyTech Rental Ad 0408) | D3: Samim Khatri (9016894002) | E3: Zeel Mudaliyar | F3: New | G3: Not Assigned | H3: N/A (Not Assigned) | I3: -
A4: 46293.486 | B4: 1. Today (28-Sep) | C4: Webhook API (NB PropertyTech Rental Ad 0408) | D4: Samim Khatri (9016894002) | E4: Zeel Mudaliyar | F4: New | G4: Not Assigned | H4: N/A (Not Assigned) | I4: -
A5: 46293.321 | B5: 1. Today (28-Sep) | C5: Meta Ads (NB PropertyTech Rental Ad 0408) | D5: Anil Khatri (9429510554) | E5: Unassigned | F5: Listed | G5: Not Assigned | H5: N/A (Not Assigned) | I5: -
A6: 46293.32 | B6: 1. Today (28-Sep) | C6: Webhook API (NB PropertyTech Rental Ad 0408) | D6: Anil Khatri (9429510554) | E6: Zeel Mudaliyar | F6: Listed | G6: Not Assigned | H6: N/A (Not Assigned) | I6: -
A7: 46292.921 | B7: 2. This Week (Last 7 Days) | C7: Housing.com (Koba) | D7: Vivek Singh (owner) (9426372931) | E7: Zeel Mudaliyar | F7: New | G7: Not Assigned | H7: N/A (Not Assigned) | I7: -
A8: 46292.816 | B8: 2. This Week (Last 7 Days) | C8: Meta Ads (NB PropertyTech Rental Ad 0408) | D8: Geeta Khatri (8368098432) | E8: Zeel Mudaliyar | F8: New | G8: Not Assigned | H8: N/A (Not Assigned) | I8: -
A9: 46292.815 | B9: 2. This Week (Last 7 Days) | C9: Webhook API (NB PropertyTech Rental Ad 0408) | D9: Geeta Khatri (8368098432) | E9: Prexa Vithalapara | F9: New | G9: Not Assigned | H9: N/A (Not Assigned) | I9: -
A10: 46292.788 | B10: 2. This Week (Last 7 Days) | C10: Webhook API (NB PropertyTech Rental Ad 0408) | D10: Ashutosh Shingala (9737938603) | E10: Zeel Mudaliyar | F10: New | G10: Not Assigned | H10: N/A (Not Assigned) | I10: -
A11: 46292.721 | B11: 2. This Week (Last 7 Days) | C11: Meta Ads (NB PropertyTech Rental Ad 0408) | D11: Janvi Gandhi (7069793887) | E11: Zeel Mudaliyar | F11: New | G11: Not Assigned | H11: N/A (Not Assigned) | I11: -
A12: 46292.721 | B12: 2. This Week (Last 7 Days) | C12: Webhook API (NB PropertyTech Rental Ad 0408) | D12: Janvi Gandhi (7069793887) | E12: Zeel Mudaliyar | F12: New | G12: Not Assigned | H12: N/A (Not Assigned) | I12: -
A13: 46292.449 | B13: 2. This Week (Last 7 Days) | C13: Webhook API (NB PropertyTech Rental Ad 0408) | D13: Kiru (7572958316) | E13: Zeel Mudaliyar | F13: New | G13: Not Assigned | H13: N/A (Not Assigned) | I13: -
... A414: 46286.483 | B414: 3. This Month (Sep 2026) | C414: Direct Property / Walk-in | D414: Shashtrinagar - Jaimin Rathod (9016134877 | E414: Direct CRM Listing | F414: Listed on PropKart (Rented Out) | G414: Daksh Jasoliya | H414: Onboarded (Rented Out) | I414: -
A415: 46284.739 | B415: 3. This Month (Sep 2026) | C415: Direct Property / Walk-in | D415: testing property - kjdkcjas (1326568979 | E415: Direct CRM Listing | F415: Listed on PropKart (Available) | G415: Propkart Admin | H415: Onboarded (Available)
A416: 46284.695 | B416: 3. This Month (Sep 2026) | C416: Direct Property / Walk-in | D416: Shree Krishna Center, near Bank Of Baroda - Sunil Chaterjee (6353676023 | E416: Direct CRM Listing | F416: Listed on PropKart (Available) | G416: Zeel Mudaliyar | H416: Onboarded (Available) | I416: -
A417: 46284.677 | B417: 3. This Month (Sep 2026) | C417: Direct Property / Walk-in | D417: Aakash Residency - Bhadresh Solanki (9825005069 | E417: Direct CRM Listing | F417: Listed on PropKart (Available) | G417: Daksh Jasoliya | H417: Onboarded (Available) | I417: -
A418: 46284.668 | B418: 3. This Month (Sep 2026) | C418: Direct Property / Walk-in | D418: Shyamvilla Bungalows - Pratik bhai (9228121713 | E418: Direct CRM Listing | F418: Listed on PropKart (Available) | G418: Daksh Jasoliya | H418: Onboarded (Available) | I418: -
A419: 46284.448 | B419: 3. This Month (Sep 2026) | C419: Direct Property / Walk-in | D419: Shrifal Apartments Gota - Kishor bhai (9824940006 | E419: Direct CRM Listing | F419: Listed on PropKart (Rented Out) | G419: Somel Rathod | H419: Onboarded (Rented Out) | I419: -
A420: 46283.668 | B420: 3. This Month (Sep 2026) | C420: Direct Property / Walk-in | D420: Aroma Residency - Williams bhai (7096040390 | E420: Direct CRM Listing | F420: Listed on PropKart (Available) | G420: Rajan Purani | H420: Onboarded (Available) | I420: -
A421: 46282.727 | B421: 3. This Month (Sep 2026) | C421: Direct Property / Walk-in | D421: Goyal Mayfair - Vidhan bahi (9898779777 | E421: Direct CRM Listing | F421: Listed on PropKart (Available) | G421: Rajan Purani | H421: Onboarded (Available) | I421: -
A422: 46279.536 | B422: 3. This Month (Sep 2026) | C422: Direct Property / Walk-in | D422: saral privesh - Jagdish meen (9724176176 | E422: Direct CRM Listing | F422: Listed on PropKart (Available) | G422: Rakesh Jadav | H422: Onboarded (Available) | I422: -
A423: 46278.97 | B423: 3. This Month (Sep 2026) | C423: Direct Property / Walk-in | D423: Singapore - segsgdfg (1946758683 | E423: Direct CRM Listing | F423: Listed on PropKart (Available) | G423: Propkart Admin | H423: Onboarded (Available) | I423: cscscac
A424: 46275.79 | B424: 3. This Month (Sep 2026) | C424: Direct Property / Walk-in | D424: akash reccidency - SMITA MAM (9978937501 | E424: Direct CRM Listing | F424: Listed on PropKart (Available) | G424: Rakesh Jadav | H424: Onboarded (Available) | I424: -
A425: 46275.615 | B425: 3. This Month (Sep 2026) | C425: Direct Property / Walk-in | D425: Harmoni harikesh - Akhil Prajapati (8765432190 | E425: Direct CRM Listing | F425: Listed on PropKart (Available) | G425: Propkart Admin | H425: Onboarded (Available) | I425: ....
A426: 46274.789 | B426: 3. This Month (Sep 2026) | C426: Direct Property / Walk-in | D426: Devsshi fatania - Devshi bhai (9265488925 | E426: Direct CRM Listing | F426: Listed on PropKart (Available) | G426: Rakesh Jadav | H426: Onboarded (Available) | I426: -
A427: 46274.537 | B427: 3. This Month (Sep 2026) | C427: Direct Property / Walk-in | D427: nirgune rise - mahesh jagani | E427: Direct CRM Listing | F427: Listed on PropKart (Available) | G427: Rakesh Jadav | H427: Onboarded (Available) | I427: -
... A481: 46220.713 | B481: 4. This Year (2026) | C481: Direct Property / Walk-in | D481: La Habitat - GD Maghnani (9414394220 | E481: Direct CRM Listing | F481: Listed on PropKart (Available) | G481: Rajan Purani | H481: Onboarded (Available) | I481: monday call kari ne photos mate javu

Sheet Requirement
A1: date | B1: date filter | C1: lead source | D1: lead name | E1: allocated telecaller | F1: current status | G1: if assigned -- sales user name | H1: sales user toggled current status | I1: remarks
A2: 46293.759 | B2: 1. Today (28-Sep) | C2: Direct | D2: Vivek Singh (9426372931) | E2: Zeel Mudaliyar | F2: New | G2: Rajan Purani | H2: New | I2: Location - Motera, Koba, Raysan and nearby area, Bunglow with some outdoor space and parking preffered | CRM: Location - Motera, Koba, Raysan and nearby area, Bunglow with some outdoor space and parking preffered
A3: 46293.673 | B3: 1. Today (28-Sep) | C3: Meta Ads (NB PropertyTech Survey Ad 3108) | D3: Vensi Pokiya (9327036161) | E3: Zeel Mudaliyar | F3: New | G3: Not Assigned | H3: N/A (Not Assigned) | I3: -
A4: 46293.649 | B4: 1. Today (28-Sep) | C4: Meta Ads (NB PropertyTech Survey Ad 3108) | D4: Shashank Tatu (9879919438) | E4: Zeel Mudaliyar | F4: New | G4: Not Assigned | H4: N/A (Not Assigned) | I4: -
A5: 46293.575 | B5: 1. Today (28-Sep) | C5: Meta Ads (NB PropertyTech Survey Ad 3108) | D5: Devika Ck Devika (9173685744) | E5: Zeel Mudaliyar | F5: New | G5: Not Assigned | H5: N/A (Not Assigned) | I5: -
A6: 46293.556 | B6: 1. Today (28-Sep) | C6: Housing.com (Navrangpura) | D6: Vishwrajsinh Jadeja (9265422446) | E6: Zeel Mudaliyar | F6: Sales | G6: Viral Jadeja | H6: Assigned | I6: Transfer: SG Highway, Gota, Thaltej, Bopal, 400-500 sq ft, budget 25-30 K, Fully furnished, office commercial property | Transfer Note: SG Highway, Gota, Thaltej, Bopal, 400-500 sq ft, budget 25-30 K, Fully furnished, office commercial property | CRM: [Telecaller Key Points]: SG Highway, Gota, Thaltej, Bopal, 400-500 sq ft, budget 25-30 K, Fully furnished, office commercial property | [Telecaller Key Points]: SG Highway, Gota, Thaltej, Bopal, 400-500 sq ft, budget 25-30 K, Fully furnished, office commercial property | SG Highway, Gota, Thaltej, Bopal, 400-500 sq ft, budget 25-30 K, Fully furnished, office commercial property
A7: 46293.516 | B7: 1. Today (28-Sep) | C7: Meta Ads (NB PropertyTech Survey Ad 3108) | D7: Diva (7069336262) | E7: Zeel Mudaliyar | F7: New | G7: Not Assigned | H7: N/A (Not Assigned) | I7: -
A8: 46293.51 | B8: 1. Today (28-Sep) | C8: Housing.com (Naranpura) | D8: Vivek Karavadia (9512227740) | E8: Zeel Mudaliyar | F8: New | G8: Not Assigned | H8: N/A (Not Assigned) | I8: -
A9: 46293.456 | B9: 1. Today (28-Sep) | C9: Meta Ads (NB PropertyTech Survey Ad 3108) | D9: Vishal Jat (9111010777) | E9: Zeel Mudaliyar | F9: Sales | G9: Rajan Purani | H9: Assigned | I9: Transfer: Locations Gurukul, Ambawadi, Memnagar, Vastrapur, 2 BHK, for family, with 25K budget range, Semi furnished AC and Bed required, possession after 1 month | Transfer Note: Locations Gurukul, Ambawadi, Memnagar, Vastrapur, 2 BHK, for family, with 25K budget range, Semi furnished AC and Bed required, possession after 1 month | CRM: [Telecaller Key Points]: Locations Gurukul, Ambawadi, Memnagar, Vastrapur, 2 BHK, for family, with 25K budget range, Semi furnished AC and Bed required, possession after 1 month | [Telecaller Key Points]: Locations Gurukul, Ambawadi, Memnagar, Vastrapur, 2 BHK, for family, with 25K budget range, Semi furnished AC and Bed required, possession after 1 month | Locations Gurukul, Ambawadi, Memnagar, Vastrapur, 2 BHK, for family, with 25K budget range, Semi furnished AC and Bed required, possession after 1 month
A10: 46293.453 | B10: 1. Today (28-Sep) | C10: Meta Ads (NB PropertyTech Survey Ad 3108) | D10: Pradip Chotara (9712315547) | E10: Prexa Vithalapara | F10: New | G10: Not Assigned | H10: N/A (Not Assigned) | I10: -
A11: 46293.438 | B11: 1. Today (28-Sep) | C11: Housing.com (Nava Vadaj) | D11: Mital Bride Studio (8734876967) | E11: Zeel Mudaliyar | F11: New | G11: Not Assigned | H11: N/A (Not Assigned) | I11: -
A12: 46293.396 | B12: 1. Today (28-Sep) | C12: Housing.com (Nava Vadaj) | D12: V (7974797176) | E12: Zeel Mudaliyar | F12: New | G12: Not Assigned | H12: N/A (Not Assigned) | I12: -
A13: 46293.339 | B13: 1. Today (28-Sep) | C13: Meta Ads (NB PropertyTech Survey Ad 3108) | D13: Harvi Soni (8320454975) | E13: Prexa Vithalapara | F13: New | G13: Not Assigned | H13: N/A (Not Assigned) | I13: -
... A736: 46220.549 | B736: 4. This Year (2026) | C736: Direct / Manual | D736: Rajan (8200659030) | E736: Unassigned | F736: Sales | G736: Rajan Purani | H736: Live | I736: 3 bhk semi or fully furnished | Followup: Call him | CRM: 3 bhk semi or fully furnished | CRM Followup: Call him

Sheet Inventory (Total Properties)
A1: date | B1: date filter | C1: property code | D1: title | E1: property type | F1: listing type | G1: status | H1: rent / price (₹) | I1: deposit (₹) | J1: maintenance (₹) | K1: bedrooms | L1: carpet area (sq ft) | M1: locality / area | N1: city | O1: owner name | P1: owner mobile | Q1: created by (user) | R1: remarks
A2: 46291.689 | B2: 2. This Week (Last 7 Days) | C2: PR-1194 | D2: Signature Elena,B/h Sangath Prominence, opp. CBD Mall, Zundal | E2: Flat | F2: Rent | G2: Available | H2: 22000 | I2: 22000 | J2: 0 | K2: 3 | L2: 922 | M2: Zundal | N2: Ahmedabad | O2: Aval Barochia | P2: 8866706086 | Q2: Zeel Mudaliyar | R2: -
A3: 46291.59 | B3: 2. This Week (Last 7 Days) | C3: PR-1193 | D3: Aakash 2 | E3: Flat | F3: Rent | G3: Rented Out | H3: 33000 | I3: 66000 | J3: 1500 | K3: 2 | L3: - | M3: Vastrapur | N3: Ahmedabad | O3: Karan bhai | P3: 9510877481 | Q3: Rajan Purani | R3: -
A4: 46290.753 | B4: 2. This Week (Last 7 Days) | C4: PR-1192 | D4: Sangath 2 | E4: Rowhouse/Tenament | F4: Rent | G4: Available | H4: 35000 | I4: 70000 | J4: 0 | K4: 3 | L4: 1030 | M4: Motera | N4: Ahmedabad | O4: Vivek Shah | P4: 9904902525 | Q4: Propkart Admin | R4: Semi furnished, modular kitchen, basic accesories
A5: 46290.707 | B5: 2. This Week (Last 7 Days) | C5: PR-1191 | D5: Kameshwar elite 140 | E5: Flat | F5: Rent | G5: Available | H5: 45000 | I5: 90000 | J5: 0 | K5: 3 | L5: 1342 | M5: Bodakdev | N5: Ahmedabad | O5: Jignesh mandlecha | P5: 7990733327 | Q5: Propkart Admin | R5: curtain rod, modular kitchen, fan and lights, bird nett, exhaust fan in Bathroom and kichen, adani Gas line
A6: 46290.662 | B6: 2. This Week (Last 7 Days) | C6: PR-1190 | D6: Jasmine Green 1 | E6: Flat | F6: Rent | G6: Available | H6: 16000 | I6: 32000 | J6: 2250 | K6: 2 | L6: 608 | M6: Vaishnodevi | N6: Ahmedabad | O6: Hardik Nayak | P6: 9724409089 | Q6: Propkart Admin | R6: Semi furnished, modular kitchen, bed, basic accesories, gas line Maintenance 2250
A7: 46290.65 | B7: 2. This Week (Last 7 Days) | C7: PR-1189 | D7: Sahjanand Status Bungalow | E7: Bungalow | F7: Rent | G7: Rented Out | H7: 70000 | I7: 140000 | J7: 0 | K7: 4 | L7: 1643 | M7: Science city | N7: Ahmedabad | O7: Rajan Purani | P7: 8200659030 | Q7: Propkart Admin | R7: TV, Refrigerator, AC, Fully furnished
A8: 46290.636 | B8: 2. This Week (Last 7 Days) | C8: PR-1188 | D8: Ratnadeep Complex | E8: Flat | F8: Rent | G8: Available | H8: 40000 | I8: 80000 | J8: 0 | K8: 3 | L8: 1250 | M8: - | N8: Ahmedabad | O8: Pathik Brahmkshatriya | P8: 9727603446 | Q8: Propkart Admin | R8: Two Split ACs, Sofa (3+2), Dining Table with 4 Chairs, CNG Gas connection, Refrigerator, Furnished Kitchen with store room, Center table, Dressing Table, Wardrobes, Double bed with Mattresses, Temple Altar
A9: 46290.609 | B9: 2. This Week (Last 7 Days) | C9: PR-1187 | D9: Diwali Blessings | E9: Flat | F9: Rent | G9: Available | H9: 35000 | I9: 70000 | J9: 0 | K9: 3 | L9: 787 | M9: Vaishnodevi | N9: Ahmedabad | O9: Uma Vyas | P9: 7043336692 | Q9: Propkart Admin | R9: Furnished Kitchen, folding dining, TV, AC, Gyzer, Ro, Refridgerator, Washing machine, fully furnished
A10: 46290.598 | B10: 2. This Week (Last 7 Days) | C10: PR-1186 | D10: Shop Sagar Avenue | E10: Office | F10: Rent | G10: Available | H10: 13000 | I10: 26000 | J10: 0 | K10: 1 | L10: 110 | M10: Ashram Road | N10: Ahmedabad | O10: Pradeep Pithadiya | P10: 9016337978 | Q10: Propkart Admin | R10: -
A11: 46290.592 | B11: 2. This Week (Last 7 Days) | C11: PR-1185 | D11: Chandraprabhu Krupa Society | E11: Rowhouse/Tenament | F11: Rent | G11: Available | H11: 30000 | I11: 60000 | J11: 0 | K11: 3 | L11: 1417.5 | M11: Ranip | N11: Ahmedabad | O11: Parmeshwar | P11: 9265031372 | Q11: Propkart Admin | R11: Semi furnished, modular kitchen, basic accesories
A12: 46290.547 | B12: 2. This Week (Last 7 Days) | C12: PR-1184 | D12: Suyash Status , Near Capital 1 Science city | E12: Flat | F12: Rent | G12: Available | H12: 35000 | I12: 35000 | J12: 0 | K12: 3 | L12: 1400 | M12: Science city | N12: Ahmedabad | O12: Viral bhai | P12: 9016134878 | Q12: Propkart Admin | R12: Viral bhai ae aa property mokli che other details mate Viral bhai ne contact kro
A13: 46290.538 | B13: 2. This Week (Last 7 Days) | C13: PR-1183 | D13: Riverside park park, New Vasna | E13: Flat | F13: Rent | G13: Available | H13: 17000 | I13: 34000 | J13: 0 | K13: 2 | L13: 571 | M13: Vasna | N13: Ahmedabad | O13: Ashmita Patel | P13: 9510187511 | Q13: Propkart Admin | R13: Semi furnished, modular kitchen, bed, basic accesories
A14: 46290.534 | B14: 2. This Week (Last 7 Days) | C14: PR-1182 | D14: RJ Pashmina | E14: Flat | F14: Rent | G14: Available | H14: 35000 | I14: 35000 | J14: 0 | K14: 3 | L14: 1512 | M14: Chandkheda | N14: Ahmedabad | O14: Bhavik Kareliya | P14: 9824143858 | Q14: Propkart Admin | R14: -
A15: 46290.527 | B15: 2. This Week (Last 7 Days) | C15: PR-1181 | D15: MOONLIGHT COMPLEX OPP GURUKUL TEMPLE GURUKUL | E15: Shop | F15: Rent | G15: Available | H15: 11000 | I15: 22000 | J15: 0 | K15: 1 | L15: 117 | M15: Gurukul | N15: Ahmedabad | O15: Mukesh Jain | P15: 9638699860 | Q15: Propkart Admin | R15: -
... A19: 46290.492 | B19: 2. This Week (Last 7 Days) | C19: PR-1177 | D19: Shivranjni Society | E19: Rowhouse/Tenament | F19: Rent | G19: Available | H19: 25000 | I19: 50000 | J19: 333 | K19: 2 | L19: 600 | M19: Satellite | N19: Ahmedabad | O19: Ramesh Padia | P19: 9898467025 | Q19: Propkart Admin | R19: 4k per year, electricity bill excluded
A20: 46289.924 | B20: 2. This Week (Last 7 Days) | C20: PR-1176 | D20: shivanta regel zundal | E20: Flat | F20: Re-Sale | G20: Available | H20: 7500000 | I20: 0 | J20: 0 | K20: 3 | L20: - | M20: Vaishnodevi | N20: Ahmedabad | O20: karan bhai | P20: 9227087898 | Q20: Rakesh Jadav | R20: invester flate che sara rate ma
A21: 46289.787 | B21: 2. This Week (Last 7 Days) | C21: PR-1175 | D21: super city bhadaj | E21: Bungalow | F21: Rent | G21: Rented Out | H21: 39000 | I21: 78000 | J21: 4000 | K21: 4 | L21: 2000 | M21: Bhadaj | N21: Ahmedabad | O21: indu ben | P21: 9427132974 | Q21: Rakesh Jadav | R21: -
A22: 46289.69 | B22: 2. This Week (Last 7 Days) | C22: PR-1174 | D22: Daffodils PLAZA, Gala Gymkhana Road South Bopal | E22: Office | F22: Rent | G22: Available | H22: 30000 | I22: 30000 | J22: 0 | K22: 1 | L22: 594 | M22: South Bopal | N22: Ahmedabad | O22: Rajendra Jadav | P22: 9879160888 | Q22: Prexa Vithalapara | R22: 2 months deposit and pay advanvce rent every month
A23: 46289.619 | B23: 2. This Week (Last 7 Days) | C23: PR-1173 | D23: Suryansh Sanidhya Shivalaya, behind Sun Estate, near Ujala Cross road, Sarkhej, SG Highway, Ahmedabad | E23: Flat | F23: Rent | G23: Available | H23: 22000 | I23: 22000 | J23: 0 | K23: 2 | L23: 540 | M23: sarkhej | N23: Ahmedabad | O23: Girish Gohil | P23: 9909915052 | Q23: Zeel Mudaliyar | R23: -
A24: 46288.611 | B24: 2. This Week (Last 7 Days) | C24: PR-1172 | D24: Maher-5 | E24: Flat | F24: Rent | G24: Available | H24: 22000 | I24: 22000 | J24: 2000 | K24: 2 | L24: 659 | M24: Shela | N24: Ahmedabad | O24: Divyesh Ruparel | P24: 8306640345 | Q24: Daksh Jasoliya | R24: Semi furnished, modular kitchen, basic accesories, Geyser
A25: 46288.604 | B25: 2. This Week (Last 7 Days) | C25: PR-1171 | D25: Money plant high street | E25: Office | F25: Rent | G25: Available | H25: 45000 | I25: 45000 | J25: 0 | K25: 2 | L25: 355 | M25: - | N25: Ahmedabad | O25: Anil Mistry | P25: 9426569262 | Q25: Daksh Jasoliya | R25: Office furniture
A26: 46288.546 | B26: 2. This Week (Last 7 Days) | C26: PR-1170 | D26: GOYAL PALLADIUM | E26: Office | F26: Rent | G26: Available | H26: 43650 | I26: 87300 | J26: 2000 | K26: 1 | L26: 436 | M26: - | N26: Ahmedabad | O26: Nishita Shah | P26: 9427601721 | Q26: Daksh Jasoliya | R26: 2 AC, Partion Maintenance Charges separate
A27: 46288.477 | B27: 2. This Week (Last 7 Days) | C27: PR-1169 | D27: Mitri lake view | E27: Flat | F27: Rent | G27: Available | H27: 25000 | I27: 25000 | J27: 0 | K27: 2 | L27: 589 | M27: Zundal | N27: Ahmedabad | O27: Mamta Vora | P27: 8780327185 | Q27: Daksh Jasoliya | R27: -
A28: 46287.723 | B28: 2. This Week (Last 7 Days) | C28: PR-1168 | D28: Shivam Appartment | E28: Flat | F28: Rent | G28: Rented Out | H28: 15000 | I28: 15000 | J28: 200 | K28: 2 | L28: 888 | M28: New Vadaj | N28: Ahmedabad | O28: Dhaval Patel | P28: 9558630687 | Q28: Daksh Jasoliya | R28: Sofa, Double Bed, Dining table + warddrobe + 2 extra bed + modular kitchen, all fan + light + curtain + 2 AC point + 2 no water tank for water storage Maintenance 2500 annually
A29: 46287.494 | B29: 2. This Week (Last 7 Days) | C29: PR-1167 | D29: Pramukh park | E29: Flat | F29: Rent | G29: Available | H29: 27000 | I29: 27000 | J29: 0 | K29: 2 | L29: 810 | M29: Naranpura | N29: Ahmedabad | O29: Rajveet Singh | P29: 8264292166 | Q29: Daksh Jasoliya | R29: No Brokerage
A30: 46286.627 | B30: 3. This Month (Sep 2026) | C30: PR-1166 | D30: Madri Apartment | E30: Flat | F30: Rent | G30: Available | H30: 22000 | I30: 22000 | J30: 0 | K30: 2 | L30: 500 | M30: Memnagar | N30: Ahmedabad | O30: Umang Trivedi | P30: 9898426900 | Q30: Daksh Jasoliya | R30: -
A31: 46286.619 | B31: 3. This Month (Sep 2026) | C31: PR-1165 | D31: Sukun Arcade | E31: Office | F31: Rent | G31: Available | H31: 35000 | I31: 35000 | J31: 2800 | K31: 1 | L31: 487 | M31: Navrangpura | N31: Ahmedabad | O31: Viral Jani | P31: 9998526402 | Q31: Daksh Jasoliya | R31: Maintenance approx quarterly 8300
A32: 46286.551 | B32: 3. This Month (Sep 2026) | C32: PR-1164 | D32: Sun footprints | E32: Flat | F32: Rent | G32: Available | H32: 31000 | I32: 31000 | J32: 0 | K32: 2 | L32: 671 | M32: Shela | N32: Ahmedabad | O32: Raju Bharwad | P32: 6355323756 | Q32: Daksh Jasoliya | R32: Only vegetarian family
... A40: 46284.741 | B40: 3. This Month (Sep 2026) | C40: PR-1156 | D40: Setu Exotica | E40: Flat | F40: Rent | G40: Available | H40: 26500 | I40: 26500 | J40: 2500 | K40: 3 | L40: 1026 | M40: - | N40: Ahmedabad | O40: Dhairya Patel | P40: 8141279797 | Q40: Daksh Jasoliya | R40: 2500 maintenance
A41: 46284.739 | B41: 3. This Month (Sep 2026) | C41: PR-1155 | D41: testing property | E41: Flat | F41: Rent | G41: Available | H41: 13266 | I41: 39798 | J41: 0 | K41: 4 | L41: - | M41: - | N41: Ahmedabad | O41: kjdkcjas | P41: 1326568979 | Q41: Propkart Admin
A42: 46284.728 | B42: 3. This Month (Sep 2026) | C42: PR-1154 | D42: Savvy Studio | E42: Flat | F42: Rent | G42: Available | H42: 17000 | I42: 17000 | J42: 0 | K42: 1 | L42: 320 | M42: Gota | N42: Ahmedabad | O42: Chetan Ghediya | P42: 8734811158 | Q42: Zeel Mudaliyar | R42: Also Available for Bachelors
A43: 46284.695 | B43: 3. This Month (Sep 2026) | C43: PR-1153 | D43: Shree Krishna Center, near Bank Of Baroda | E43: Flat | F43: Rent | G43: Available | H43: 20000 | I43: 20000 | J43: 5000 | K43: 1 | L43: 170 | M43: Navrangpura | N43: Ahmedabad | O43: Sunil Chaterjee | P43: 6353676023 | Q43: Zeel Mudaliyar | R43: -
A44: 46284.677 | B44: 3. This Month (Sep 2026) | C44: PR-1152 | D44: Aakash Residency | E44: Flat | F44: Rent | G44: Available | H44: 24000 | I44: 24000 | J44: 0 | K44: 2 | L44: 463 | M44: Shela | N44: Ahmedabad | O44: Bhadresh Solanki | P44: 9825005069 | Q44: Daksh Jasoliya | R44: -
A45: 46284.668 | B45: 3. This Month (Sep 2026) | C45: PR-1151 | D45: Shyamvilla Bungalows | E45: Rowhouse/Tenament | F45: Rent | G45: Available | H45: 39000 | I45: 39000 | J45: 0 | K45: 3 | L45: 891 | M45: Sola | N45: Ahmedabad | O45: Pratik bhai | P45: 9228121713 | Q45: Daksh Jasoliya | R45: -
A46: 46284.666 | B46: 3. This Month (Sep 2026) | C46: PR-1150 | D46: Keshavbaag Capital Asopalav, Vastrapur | E46: Office | F46: Rent | G46: Available | H46: 18000 | I46: 18000 | J46: 0 | K46: 1 | L46: 675 | M46: Vastrapur | N46: Ahmedabad | O46: Mehul Soni | P46: 9904721565 | Q46: Zeel Mudaliyar | R46: -
A47: 46284.482 | B47: 3. This Month (Sep 2026) | C47: PR-1149 | D47: hvhighi | E47: Office | F47: Rent | G47: Available | H47: 100000 | I47: 200000 | J47: 0 | K47: 1 | L47: - | M47: Ambli | N47: Ahmedabad | O47: test | P47: 1234567890 | Q47: Viral Jadeja | R47: hbhi
A48: 46284.448 | B48: 3. This Month (Sep 2026) | C48: PR-1148 | D48: Shrifal Apartments Gota | E48: Flat | F48: Rent | G48: Rented Out | H48: 17200 | I48: 34400 | J48: 1200 | K48: 2 | L48: - | M48: Gota | N48: Ahmedabad | O48: Kishor bhai | P48: 9824940006 | Q48: Somel Rathod | R48: -
A49: 46283.668 | B49: 3. This Month (Sep 2026) | C49: PR-1147 | D49: Aroma Residency | E49: Flat | F49: Rent | G49: Available | H49: 35000 | I49: 70000 | J49: 1500 | K49: 3 | L49: - | M49: Vastrapur | N49: Ahmedabad | O49: Williams bhai | P49: 7096040390 | Q49: Rajan Purani | R49: -
A50: 46283.641 | B50: 3. This Month (Sep 2026) | C50: PR-1146 | D50: Basil Skyline, Vaishnodevi circle | E50: Office | F50: Rent | G50: Available | H50: 16000 | I50: 16000 | J50: 0 | K50: 3 | L50: 150 | M50: - | N50: Ahmedabad | O50: Priyal Bhatt | P50: 9408280355 | Q50: Daksh Jasoliya | R50: 17,000 + tax and maintenance
...
